Workbook

Sheet Anime List
A1: MAL ID | B1: Title | C1: Format | D1: Episodes | E1: Watched | F1: Progress % | G1: My Score | H1: Status | I1: Genres | J1: Studio | K1: Global Score | L1: MAL URL
A2: 31646 | B2: 3-gatsu no Lion | C2: TV | D2: 22 | E2: 22 | F2: =IF(D2>0, E2/D2, IF(H2="Completed", 1, 0)) | G2: 8 | H2: Completed | I2: Drama, Slice of Life | J2: Shaft | K2: 8.3 | L2: https://myanimelist.net/anime/31646
A3: 35180 | B3: 3-gatsu no Lion 2nd Season | C3: TV | D3: 22 | E3: 22 | F3: =IF(D3>0, E3/D3, IF(H3="Completed", 1, 0)) | G3: 8 | H3: Completed | I3: Drama, Slice of Life | J3: Shaft | K3: 8.9 | L3: https://myanimelist.net/anime/35180
A4: 38101 | B4: 5-toubun no Hanayome | C4: TV | D4: 12 | E4: 12 | F4: =IF(D4>0, E4/D4, IF(H4="Completed", 1, 0)) | G4: 7 | H4: Completed | I4: Comedy, Drama, Romance, Slice of Life | J4: Tezuka Productions | K4: 7.6 | L4: https://myanimelist.net/anime/38101
A5: 39783 | B5: 5-toubun no Hanayome ∬ | C5: TV | D5: 12 | E5: 12 | F5: =IF(D5>0, E5/D5, IF(H5="Completed", 1, 0)) | G5: 7 | H5: Completed | I5: Comedy, Drama, Romance, Slice of Life | J5: Bibury Animation Studios | K5: 8 | L5: https://myanimelist.net/anime/39783
A6: 6547 | B6: Angel Beats! | C6: TV | D6: 13 | E6: 13 | F6: =IF(D6>0, E6/D6, IF(H6="Completed", 1, 0)) | G6: 9 | H6: Completed | I6: Action, Comedy, Drama, Supernatural | J6: P.A.WORKS | K6: 7.7 | L6: https://myanimelist.net/anime/6547
A7: 9989 | B7: Ano Hi Mita Hana no Namae wo Bokutachi wa Mada Shiranai. | C7: TV | D7: 11 | E7: 11 | F7: =IF(D7>0, E7/D7, IF(H7="Completed", 1, 0)) | G7: 9 | H7: Completed | I7: Drama, Romance, Slice of Life, Supernatural | J7: A-1 Pictures | K7: 8 | L7: https://myanimelist.net/anime/9989
A8: 15039 | B8: Ano Hi Mita Hana no Namae wo Bokutachi wa Mada Shiranai. Movie | C8: Movie | D8: 1 | E8: 1 | F8: =IF(D8>0, E8/D8, IF(H8="Completed", 1, 0)) | G8: 6 | H8: Completed | I8: Drama, Romance, Slice of Life, Supernatural | J8: A-1 Pictures | K8: 7.6 | L8: https://myanimelist.net/anime/15039
A9: 21995 | B9: Ao Haru Ride | C9: TV | D9: 12 | E9: 12 | F9: =IF(D9>0, E9/D9, IF(H9="Completed", 1, 0)) | G9: 5 | H9: Completed | I9: Drama, Romance, Slice of Life | J9: Production I.G | K9: 7.5 | L9: https://myanimelist.net/anime/21995
A10: 38753 | B10: Araburu Kisetsu no Otome-domo yo. | C10: TV | D10: 12 | E10: 12 | F10: =IF(D10>0, E10/D10, IF(H10="Completed", 1, 0)) | G10: 7 | H10: Completed | I10: Comedy, Drama, Romance, Slice of Life | J10: Lay-duce | K10: 7.1 | L10: https://myanimelist.net/anime/38753
A11: 6347 | B11: Baka to Test to Shoukanjuu | C11: TV | D11: 13 | E11: 13 | F11: =IF(D11>0, E11/D11, IF(H11="Completed", 1, 0)) | G11: 7 | H11: Completed | I11: Comedy, Romance | J11: SILVER LINK. | K11: 7.1 | L11: https://myanimelist.net/anime/6347
A12: 8516 | B12: Baka to Test to Shoukanjuu Ni! | C12: TV | D12: 13 | E12: 13 | F12: =IF(D12>0, E12/D12, IF(H12="Completed", 1, 0)) | G12: 7 | H12: Completed | I12: Comedy, Romance, Slice of Life | J12: SILVER LINK. | K12: 7.4 | L12: https://myanimelist.net/anime/8516
A13: 28805 | B13: Bakemono no Ko | C13: Movie | D13: 1 | E13: 1 | F13: =IF(D13>0, E13/D13, IF(H13="Completed", 1, 0)) | G13: 8 | H13: Completed | I13: Action, Adventure, Comedy, Drama, Fantasy, Supernatural | J13: Studio Chizu | K13: 7.9 | L13: https://myanimelist.net/anime/28805
... A220: 52034 | B220: [Oshi no Ko] | C220: TV | D220: 11 | E220: 11 | F220: =IF(D220>0, E220/D220, IF(H220="Completed", 1, 0)) | G220: 8 | H220: Completed | I220: Drama, Mystery, Psychological, Supernatural | J220: Doga Kobo | K220: 8.4 | L220: https://myanimelist.net/anime/52034

Sheet Manga List
A1: MAL ID | B1: Title | C1: Type | D1: Chapters | E1: Volumes | F1: Read Chapters | G1: Read Volumes | H1: Progress % | I1: My Score | J1: Status | K1: Genres | L1: Authors | M1: Global Score | N1: MAL URL
A2: 103851 | B2: 5-toubun no Hanayome | C2: Manga | D2: 122 | E2: 14 | F2: 122 | G2: 14 | H2: =IF(D2>0, F2/D2, IF(J2="Completed", 1, 0)) | I2: 8 | J2: Completed | K2: Comedy, Drama, Romance | L2: Negi Haruba | M2: 7.7 | N2: https://myanimelist.net/manga/103851
A3: 24705 | B3: Aku no Hana | C3: Manga | D3: 58 | E3: 11 | F3: 58 | G3: 11 | H3: =IF(D3>0, F3/D3, IF(J3="Completed", 1, 0)) | I3: 9 | J3: Completed | K3: Drama, Psychological, Romance | L3: Shuuzou Oshimi | M3: 8.1 | N3: https://myanimelist.net/manga/24705
A4: 2 | B4: Berserk | C4: Manga | D4: 0 | E4: 0 | F4: 380 | G4: 41 | H4: =IF(D4>0, F4/D4, IF(J4="Completed", 1, 0)) | I4: 10 | J4: Completed | K4: Action, Adventure, Drama, Fantasy, Horror, Psychological | L4: Kentarou Miura, Studio Gaga | M4: 9.2 | N4: https://myanimelist.net/manga/2
A5: 23419 | B5: Byousoku 5 Centimeter | C5: Manga | D5: 11 | E5: 2 | F5: 11 | G5: 2 | H5: =IF(D5>0, F5/D5, IF(J5="Completed", 1, 0)) | I5: 9 | J5: Completed | K5: Drama, Romance | L5: Makoto Shinkai, Yukiko Seike | M5: 7.4 | N5: https://myanimelist.net/manga/23419
A6: 116778 | B6: Chainsaw Man | C6: Manga | D6: 232 | E6: 24 | F6: 9 | G6: 0 | H6: =IF(D6>0, F6/D6, IF(J6="Completed", 1, 0)) | I6: 7 | J6: Reading | K6: Action, Comedy, Drama, Horror, Supernatural | L6: Tatsuki Fujimoto | M6: 8.5 | N6: https://myanimelist.net/manga/116778
A7: 104271 | B7: Chi no Wadachi | C7: Manga | D7: 153 | E7: 17 | F7: 0 | G7: 0 | H7: =IF(D7>0, F7/D7, IF(J7="Completed", 1, 0)) | I7: 0 | J7: Reading | K7: Drama, Horror, Psychological | L7: Shuuzou Oshimi | M7: 8 | N7: https://myanimelist.net/manga/104271
A8: 135496 | B8: Dandadan | C8: Manga | D8: 0 | E8: 0 | F8: 0 | G8: 0 | H8: =IF(D8>0, F8/D8, IF(J8="Completed", 1, 0)) | I8: 0 | J8: Reading | K8: Action, Comedy, Drama, Romance, Sci-Fi, Supernatural | L8: Yukinobu Tatsu | M8: 8.2 | N8: https://myanimelist.net/manga/135496
A9: 70801 | B9: Dead Dead Demons Dededede Destruction | C9: Manga | D9: 101 | E9: 12 | F9: 0 | G9: 0 | H9: =IF(D9>0, F9/D9, IF(J9="Completed", 1, 0)) | I9: 0 | J9: Reading | K9: Comedy, Drama, Sci-Fi, Slice of Life | L9: Inio Asano, Eric Montesinos | M9: 8.1 | N9: https://myanimelist.net/manga/70801
A10: 65981 | B10: Henshin | C10: Manga | D10: 7 | E10: 1 | F10: 7 | G10: 1 | H10: =IF(D10>0, F10/D10, IF(J10="Completed", 1, 0)) | I10: 7 | J10: Completed | K10: Drama, Hentai | L10: Eru Shindou | M10: 6.4 | N10: https://myanimelist.net/manga/65981
A11: 936 | B11: Homunculus | C11: Manga | D11: 166 | E11: 15 | F11: 0 | G11: 0 | H11: =IF(D11>0, F11/D11, IF(J11="Completed", 1, 0)) | I11: 0 | J11: Reading | K11: Drama, Horror, Mystery, Psychological, Supernatural | L11: Hideo Yamamoto | M11: 8.3 | N11: https://myanimelist.net/manga/936
A12: 42451 | B12: Horimiya | C12: Manga | D12: 139 | E12: 17 | F12: 0 | G12: 16 | H12: =IF(D12>0, F12/D12, IF(J12="Completed", 1, 0)) | I12: 6 | J12: Completed | K12: Comedy, Romance, Slice of Life | L12: Daisuke Hagiwara, HERO, Studio Charon | M12: 8.2 | N12: https://myanimelist.net/manga/42451
A13: 105084 | B13: Jibaku Shounen Hanako-kun | C13: Manga | D13: 0 | E13: 0 | F13: 0 | G13: 0 | H13: =IF(D13>0, F13/D13, IF(J13="Completed", 1, 0)) | I13: 0 | J13: Reading | K13: Action, Comedy, Drama, Mystery, Romance, Supernatural | L13: AidaIro | M13: 8.5 | N13: https://myanimelist.net/manga/105084
... A48: 126146 | B48: [Oshi no Ko] | C48: Manga | D48: 171 | E48: 16 | F48: 0 | G48: 0 | H48: =IF(D48>0, F48/D48, IF(J48="Completed", 1, 0)) | I48: 0 | J48: Reading | K48: Drama, Mystery, Psychological, Supernatural | L48: Aka Akasaka, Mengo Yokoyari | M48: 7.8 | N48: https://myanimelist.net/manga/126146

Sheet Overview & Stats
B2: ANIMANGA SHOWCASE — EXECUTIVE ANALYTICS DASHBOARD
B3: Real-time Metrics & Insights for 219 Anime & 47 Manga • Powered by MyAnimeList Export Data
B5: EXECUTIVE SUMMARY KPIS
B6: TOTAL TITLES | E6: TOTAL ANIME | H6: TOTAL MANGA
B7: =COUNTA('Anime List'!B2:B220) + COUNTA('Manga List'!B2:B48) | E7: =COUNTA('Anime List'!B2:B220) | H7: =COUNTA('Manga List'!B2:B48)
B10: TOTAL EPISODES WATCHED | E10: TOTAL CHAPTERS READ | H10: ANIME MEAN SCORE (RATED)
B11: =SUM('Anime List'!E2:E220) | E11: =SUM('Manga List'!F2:F48) | H11: =AVERAGEIF('Anime List'!G2:G220, ">0")
B14: MANGA MEAN SCORE (RATED) | E14: ANIME COMPLETION RATE | H14: MANGA COMPLETION RATE
B15: =AVERAGEIF('Manga List'!I2:I48, ">0") | E15: =COUNTIF('Anime List'!H2:H220, "Completed") / COUNTA('Anime List'!B2:B220) | H15: =COUNTIF('Manga List'!J2:J48, "Completed") / COUNTA('Manga List'!B2:B48)
B18: STATUS BREAKDOWN | H18: SCORE DISTRIBUTION
B19: Status | C19: Anime | D19: Manga | E19: Total | F19: % Share | H19: Score Tier | I19: Anime | J19: Manga | K19: Total | L19: % Share
B20: Completed | C20: =COUNTIF('Anime List'!H2:H220, "Completed") | D20: =COUNTIF('Manga List'!J2:J48, "Completed") | E20: =C20+D20 | F20: =E20/$E$25 | H20: ★ 10 Masterpiece | I20: =COUNTIF('Anime List'!G2:G220, 10) | J20: =COUNTIF('Manga List'!I2:I48, 10) | K20: =I20+J20 | L20: =K20/$K$26
B21: Watching / Reading | C21: =COUNTIF('Anime List'!H2:H220, "Watching") | D21: =COUNTIF('Manga List'!J2:J48, "Reading") | E21: =C21+D21 | F21: =E21/$E$25 | H21: ★ 9 Great | I21: =COUNTIF('Anime List'!G2:G220, 9) | J21: =COUNTIF('Manga List'!I2:I48, 9) | K21: =I21+J21 | L21: =K21/$K$26
B22: Plan to Watch / Read | C22: =COUNTIF('Anime List'!H2:H220, "Plan to Watch") | D22: =COUNTIF('Manga List'!J2:J48, "Plan to Read") | E22: =C22+D22 | F22: =E22/$E$25 | H22: ★ 7-8 Good | I22: =COUNTIF('Anime List'!G2:G220, 7) + COUNTIF('Anime List'!G2:G220, 8) | J22: =COUNTIF('Manga List'!I2:I48, 7) + COUNTIF('Manga List'!I2:I48, 8) | K22: =I22+J22 | L22: =K22/$K$26
B23: On-Hold | C23: =COUNTIF('Anime List'!H2:H220, "On-Hold") | D23: =COUNTIF('Manga List'!J2:J48, "On-Hold") | E23: =C23+D23 | F23: =E23/$E$25 | H23: ★ 5-6 Average | I23: =COUNTIF('Anime List'!G2:G220, 5) + COUNTIF('Anime List'!G2:G220, 6) | J23: =COUNTIF('Manga List'!I2:I48, 5) + COUNTIF('Manga List'!I2:I48, 6) | K23: =I23+J23 | L23: =K23/$K$26
B24: Dropped | C24: =COUNTIF('Anime List'!H2:H220, "Dropped") | D24: =COUNTIF('Manga List'!J2:J48, "Dropped") | E24: =C24+D24 | F24: =E24/$E$25 | H24: ★ 1-4 Low | I24: =COUNTIF('Anime List'!G2:G220, ">=1") - COUNTIF('Anime List'!G2:G220, ">=5") | J24: =COUNTIF('Manga List'!I2:I48, ">=1") - COUNTIF('Manga List'!I2:I48, ">=5") | K24: =I24+J24 | L24: =K24/$K$26
B25: Total | C25: =SUM(C20:C24) | D25: =SUM(D20:D24) | E25: =SUM(E20:E24) | F25: =SUM(F20:F24) | H25: Unrated (0) | I25: =COUNTIF('Anime List'!G2:G220, 0) | J25: =COUNTIF('Manga List'!I2:I48, 0) | K25: =I25+J25 | L25: =K25/$K$26
H26: Total Titles | I26: =SUM(I20:I25) | J26: =SUM(J20:J25) | K26: =SUM(K20:K25) | L26: =SUM(L20:L25)
B28: TOP 10 RATED ANIME | H28: TOP 10 RATED MANGA
B29: Rank | C29: Title | D29: Score | E29: Global | F29: Studio | H29: Rank | I29: Title | J29: Score | K29: Global | L29: Author
B30: 1 | C30: Shingeki no Kyojin Season 3 Part 2 | D30: 10 | E30: 9 | F30: WIT STUDIO | H30: 1 | I30: Berserk | J30: 10 | K30: 9.2 | L30: Kentarou Miura, Studio Gaga
B31: 2 | C31: Kaguya-sama wa Kokurasetai: Ultra Romantic | D31: 10 | E31: 8.9 | F31: A-1 Pictures | H31: 2 | I31: Oyasumi Punpun | J31: 10 | K31: 8.8 | L31: Inio Asano, Annaliese Christman
B32: 3 | C32: Steins;Gate | D32: 10 | E32: 8.9 | F32: WHITE FOX | H32: 3 | I32: Vinland Saga | J32: 9 | K32: 9 | L32: Makoto Yukimura
B33: 4 | C33: Clannad: After Story | D33: 10 | E33: 8.8 | F33: Kyoto Animation | H33: 4 | I33: Kaguya-sama wa Kokurasetai: Tensai-tachi no Renai Zunousen | J33: 9 | K33: 8.7 | L33: Aka Akasaka
B34: 5 | C34: Kimi no Na wa. | D34: 10 | E34: 8.6 | F34: CoMix Wave | H34: 5 | I34: Shingeki no Kyojin | J34: 9 | K34: 8.4 | L34: Hajime Isayama
B35: 6 | C35: Takopii no Genzai | D35: 10 | E35: 8.6 | F35: ENISHIYA | H35: 6 | I35: Solo Leveling | J35: 9 | K35: 8.4 | L35: Seong-Rak Jang, So-Ryeong Gi, Chu-Gong, Hyeon-Gun
B36: 7 | C36: Sousou no Frieren | D36: 9 | E36: 9.1 | F36: MADHOUSE | H36: 7 | I36: Onanie Master Kurosawa | J36: 9 | K36: 8.2 | L36: Takuma Yokota, Katsura Ise
B37: 8 | C37: Gintama° | D37: 9 | E37: 9 | F37: Bandai Namco Pictures | H37: 8 | I37: Aku no Hana | J37: 9 | K37: 8.1 | L37: Shuuzou Oshimi
B38: 9 | C38: Gintama' | D38: 9 | E38: 8.9 | F38: Sunrise | H38: 9 | I38: Solanin | J38: 9 | K38: 8.1 | L38: Inio Asano, Hernán Dillie
B39: 10 | C39: Gintama': Enchousen | D39: 9 | E39: 8.9 | F39: Sunrise | H39: 10 | I39: Komi-san wa, Comyushou desu. | J39: 9 | K39: 7.7 | L39: Tomohito Oda, Erwan Lossois, Eve Grandt
B41: GENRE DISTRIBUTION BREAKDOWN (TOP 10 GENRES)
B42: Genre Name | C42: Anime Count | D42: Manga Count | E42: Total Frequency | F42: % of Catalog
B43: Drama | C43: =COUNTIF('Anime List'!I$2:I$220, "*Drama*") | D43: =COUNTIF('Manga List'!K$2:K$48, "*Drama*") | E43: =C43+D43 | F43: =E43/(COUNTA('Anime List'!B$2:B$220) + COUNTA('Manga List'!B$2:B$48))
B44: Comedy | C44: =COUNTIF('Anime List'!I$2:I$220, "*Comedy*") | D44: =COUNTIF('Manga List'!K$2:K$48, "*Comedy*") | E44: =C44+D44 | F44: =E44/(COUNTA('Anime List'!B$2:B$220) + COUNTA('Manga List'!B$2:B$48))
B45: Slice of Life | C45: =COUNTIF('Anime List'!I$2:I$220, "*Slice of Life*") | D45: =COUNTIF('Manga List'!K$2:K$48, "*Slice of Life*") | E45: =C45+D45 | F45: =E45/(COUNTA('Anime List'!B$2:B$220) + COUNTA('Manga List'!B$2:B$48))
B46: Romance | C46: =COUNTIF('Anime List'!I$2:I$220, "*Romance*") | D46: =COUNTIF('Manga List'!K$2:K$48, "*Romance*") | E46: =C46+D46 | F46: =E46/(COUNTA('Anime List'!B$2:B$220) + COUNTA('Manga List'!B$2:B$48))
B47: Supernatural | C47: =COUNTIF('Anime List'!I$2:I$220, "*Supernatural*") | D47: =COUNTIF('Manga List'!K$2:K$48, "*Supernatural*") | E47: =C47+D47 | F47: =E47/(COUNTA('Anime List'!B$2:B$220) + COUNTA('Manga List'!B$2:B$48))
B48: Action | C48: =COUNTIF('Anime List'!I$2:I$220, "*Action*") | D48: =COUNTIF('Manga List'!K$2:K$48, "*Action*") | E48: =C48+D48 | F48: =E48/(COUNTA('Anime List'!B$2:B$220) + COUNTA('Manga List'!B$2:B$48))
B49: Fantasy | C49: =COUNTIF('Anime List'!I$2:I$220, "*Fantasy*") | D49: =COUNTIF('Manga List'!K$2:K$48, "*Fantasy*") | E49: =C49+D49 | F49: =E49/(COUNTA('Anime List'!B$2:B$220) + COUNTA('Manga List'!B$2:B$48))
B50: Psychological | C50: =COUNTIF('Anime List'!I$2:I$220, "*Psychological*") | D50: =COUNTIF('Manga List'!K$2:K$48, "*Psychological*") | E50: =C50+D50 | F50: =E50/(COUNTA('Anime List'!B$2:B$220) + COUNTA('Manga List'!B$2:B$48))
...
